2022-05-12 16:52:00,891 - apscheduler.scheduler - INFO - Scheduler started
2022-05-12 16:52:02,412 - error - ERROR - Exception while handling an update:
Traceback (most recent call last):
  File "C:\Users\user\AppData\Local\Programs\Python\Python39\lib\site-packages\telegram\ext\dispatcher.py", line 555, in process_update
    handler.handle_update(update, self, check, context)
  File "C:\Users\user\AppData\Local\Programs\Python\Python39\lib\site-packages\telegram\ext\handler.py", line 198, in handle_update
    return self.callback(update, context)
  File "c:\Users\user\CometovArt\Dev\catbot\command.py", line 47, in test
    date2 = datetime.now()
AttributeError: module 'datetime' has no attribute 'now'
2022-05-12 16:52:02,849 - error - ERROR - Exception while handling an update:
Traceback (most recent call last):
  File "C:\Users\user\AppData\Local\Programs\Python\Python39\lib\site-packages\telegram\ext\dispatcher.py", line 555, in process_update
    handler.handle_update(update, self, check, context)
  File "C:\Users\user\AppData\Local\Programs\Python\Python39\lib\site-packages\telegram\ext\handler.py", line 198, in handle_update
    return self.callback(update, context)
  File "c:\Users\user\CometovArt\Dev\catbot\command.py", line 47, in test
    date2 = datetime.now()
AttributeError: module 'datetime' has no attribute 'now'
2022-05-12 16:52:03,030 - error - ERROR - Exception while handling an update:
Traceback (most recent call last):
  File "C:\Users\user\AppData\Local\Programs\Python\Python39\lib\site-packages\telegram\ext\dispatcher.py", line 555, in process_update
    handler.handle_update(update, self, check, context)
  File "C:\Users\user\AppData\Local\Programs\Python\Python39\lib\site-packages\telegram\ext\handler.py", line 198, in handle_update
    return self.callback(update, context)
  File "c:\Users\user\CometovArt\Dev\catbot\command.py", line 47, in test
    date2 = datetime.now()
AttributeError: module 'datetime' has no attribute 'now'
2022-05-12 16:52:03,212 - error - ERROR - Exception while handling an update:
Traceback (most recent call last):
  File "C:\Users\user\AppData\Local\Programs\Python\Python39\lib\site-packages\telegram\ext\dispatcher.py", line 555, in process_update
    handler.handle_update(update, self, check, context)
  File "C:\Users\user\AppData\Local\Programs\Python\Python39\lib\site-packages\telegram\ext\handler.py", line 198, in handle_update
    return self.callback(update, context)
  File "c:\Users\user\CometovArt\Dev\catbot\command.py", line 47, in test
    date2 = datetime.now()
AttributeError: module 'datetime' has no attribute 'now'
2022-05-12 16:52:45,857 - apscheduler.scheduler - INFO - Scheduler started
2022-05-12 16:52:50,789 - error - ERROR - Exception while handling an update:
Traceback (most recent call last):
  File "C:\Users\user\AppData\Local\Programs\Python\Python39\lib\site-packages\telegram\ext\dispatcher.py", line 555, in process_update
    handler.handle_update(update, self, check, context)
  File "C:\Users\user\AppData\Local\Programs\Python\Python39\lib\site-packages\telegram\ext\handler.py", line 198, in handle_update
    return self.callback(update, context)
  File "c:\Users\user\CometovArt\Dev\catbot\command.py", line 46, in test
    date = datetime.datetime.today().strftime("%H-%M")
AttributeError: type object 'datetime.datetime' has no attribute 'datetime'
2022-05-12 16:53:36,358 - apscheduler.scheduler - INFO - Scheduler started
2022-05-12 16:54:19,731 - apscheduler.scheduler - INFO - Scheduler started
2022-05-12 18:57:58,946 - apscheduler.scheduler - INFO - Scheduler started
2022-05-12 18:59:49,169 - apscheduler.scheduler - INFO - Scheduler started
2022-05-12 18:59:49,617 - error - ERROR - Exception while handling an update:
Traceback (most recent call last):
  File "C:\Users\user\AppData\Local\Programs\Python\Python39\lib\site-packages\telegram\ext\dispatcher.py", line 555, in process_update
    handler.handle_update(update, self, check, context)
  File "C:\Users\user\AppData\Local\Programs\Python\Python39\lib\site-packages\telegram\ext\handler.py", line 198, in handle_update
    return self.callback(update, context)
  File "c:\Users\user\CometovArt\Dev\catbot\command.py", line 46, in test
    worksheet2 = sh.worksheet('test2')
NameError: name 'sh' is not defined
2022-05-12 19:01:02,398 - apscheduler.scheduler - INFO - Scheduler started
2022-05-12 19:02:51,344 - apscheduler.scheduler - INFO - Scheduler started
2022-05-12 19:06:31,733 - apscheduler.scheduler - INFO - Scheduler started
2022-05-12 19:07:39,292 - apscheduler.scheduler - INFO - Scheduler started
2022-05-12 19:28:05,216 - telegram.ext.updater - ERROR - Error while getting Updates: urllib3 HTTPError ('Connection aborted.', RemoteDisconnected('Remote end closed connection without response'))
2022-05-12 19:28:05,229 - error - ERROR - Exception while handling an update:
Traceback (most recent call last):
  File "C:\Users\user\AppData\Local\Programs\Python\Python39\lib\site-packages\telegram\vendor\ptb_urllib3\urllib3\connectionpool.py", line 614, in urlopen
    httplib_response = self._make_request(conn, method, url,
  File "C:\Users\user\AppData\Local\Programs\Python\Python39\lib\site-packages\telegram\vendor\ptb_urllib3\urllib3\connectionpool.py", line 402, in _make_request
    six.raise_from(e, None)
  File "<string>", line 2, in raise_from
  File "C:\Users\user\AppData\Local\Programs\Python\Python39\lib\site-packages\telegram\vendor\ptb_urllib3\urllib3\connectionpool.py", line 398, in _make_request
    httplib_response = conn.getresponse()
  File "C:\Users\user\AppData\Local\Programs\Python\Python39\lib\http\client.py", line 1377, in getresponse
    response.begin()
  File "C:\Users\user\AppData\Local\Programs\Python\Python39\lib\http\client.py", line 320, in begin
    version, status, reason = self._read_status()
  File "C:\Users\user\AppData\Local\Programs\Python\Python39\lib\http\client.py", line 289, in _read_status
    raise RemoteDisconnected("Remote end closed connection without"
http.client.RemoteDisconnected: Remote end closed connection without response

During handling of the above exception, another exception occurred:

Traceback (most recent call last):
  File "C:\Users\user\AppData\Local\Programs\Python\Python39\lib\site-packages\telegram\utils\request.py", line 259, in _request_wrapper
    resp = self._con_pool.request(*args, **kwargs)
  File "C:\Users\user\AppData\Local\Programs\Python\Python39\lib\site-packages\telegram\vendor\ptb_urllib3\urllib3\request.py", line 68, in request
    return self.request_encode_body(method, url, fields=fields,
  File "C:\Users\user\AppData\Local\Programs\Python\Python39\lib\site-packages\telegram\vendor\ptb_urllib3\urllib3\request.py", line 148, in request_encode_body
    return self.urlopen(method, url, **extra_kw)
  File "C:\Users\user\AppData\Local\Programs\Python\Python39\lib\site-packages\telegram\vendor\ptb_urllib3\urllib3\poolmanager.py", line 244, in urlopen
    response = conn.urlopen(method, u.request_uri, **kw)
  File "C:\Users\user\AppData\Local\Programs\Python\Python39\lib\site-packages\telegram\vendor\ptb_urllib3\urllib3\connectionpool.py", line 665, in urlopen
    retries = retries.increment(method, url, error=e, _pool=self,
  File "C:\Users\user\AppData\Local\Programs\Python\Python39\lib\site-packages\telegram\vendor\ptb_urllib3\urllib3\util\retry.py", line 347, in increment
    raise six.reraise(type(error), error, _stacktrace)
  File "C:\Users\user\AppData\Local\Programs\Python\Python39\lib\site-packages\telegram\vendor\ptb_urllib3\urllib3\packages\six.py", line 685, in reraise
    raise value.with_traceback(tb)
  File "C:\Users\user\AppData\Local\Programs\Python\Python39\lib\site-packages\telegram\vendor\ptb_urllib3\urllib3\connectionpool.py", line 614, in urlopen
    httplib_response = self._make_request(conn, method, url,
  File "C:\Users\user\AppData\Local\Programs\Python\Python39\lib\site-packages\telegram\vendor\ptb_urllib3\urllib3\connectionpool.py", line 402, in _make_request
    six.raise_from(e, None)
  File "<string>", line 2, in raise_from
  File "C:\Users\user\AppData\Local\Programs\Python\Python39\lib\site-packages\telegram\vendor\ptb_urllib3\urllib3\connectionpool.py", line 398, in _make_request
    httplib_response = conn.getresponse()
  File "C:\Users\user\AppData\Local\Programs\Python\Python39\lib\http\client.py", line 1377, in getresponse
    response.begin()
  File "C:\Users\user\AppData\Local\Programs\Python\Python39\lib\http\client.py", line 320, in begin
    version, status, reason = self._read_status()
  File "C:\Users\user\AppData\Local\Programs\Python\Python39\lib\http\client.py", line 289, in _read_status
    raise RemoteDisconnected("Remote end closed connection without"
telegram.vendor.ptb_urllib3.urllib3.exceptions.ProtocolError: ('Connection aborted.', RemoteDisconnected('Remote end closed connection without response'))

The above exception was the direct cause of the following exception:

Traceback (most recent call last):
  File "C:\Users\user\AppData\Local\Programs\Python\Python39\lib\site-packages\telegram\ext\updater.py", line 646, in _network_loop_retry
    if not action_cb():
  File "C:\Users\user\AppData\Local\Programs\Python\Python39\lib\site-packages\telegram\ext\updater.py", line 597, in polling_action_cb
    updates = self.bot.get_updates(
  File "C:\Users\user\AppData\Local\Programs\Python\Python39\lib\site-packages\telegram\ext\extbot.py", line 224, in get_updates
    updates = super().get_updates(
  File "C:\Users\user\AppData\Local\Programs\Python\Python39\lib\site-packages\telegram\bot.py", line 130, in decorator
    result = func(*args, **kwargs)
  File "C:\Users\user\AppData\Local\Programs\Python\Python39\lib\site-packages\telegram\bot.py", line 3054, in get_updates
    self._post(
  File "C:\Users\user\AppData\Local\Programs\Python\Python39\lib\site-packages\telegram\bot.py", line 295, in _post
    return self.request.post(
  File "C:\Users\user\AppData\Local\Programs\Python\Python39\lib\site-packages\telegram\utils\request.py", line 361, in post
    result = self._request_wrapper(
  File "C:\Users\user\AppData\Local\Programs\Python\Python39\lib\site-packages\telegram\utils\request.py", line 265, in _request_wrapper
    raise NetworkError(f'urllib3 HTTPError {error}') from error
telegram.error.NetworkError: urllib3 HTTPError ('Connection aborted.', RemoteDisconnected('Remote end closed connection without response'))
2022-05-12 19:28:05,737 - telegram.ext.dispatcher - ERROR - An uncaught error was raised while handling the error.
Traceback (most recent call last):
  File "C:\Users\user\AppData\Local\Programs\Python\Python39\lib\site-packages\telegram\ext\dispatcher.py", line 536, in process_update
    self.dispatch_error(None, update)
  File "C:\Users\user\AppData\Local\Programs\Python\Python39\lib\site-packages\telegram\ext\dispatcher.py", line 810, in dispatch_error
    callback(update, context)
  File "c:\Users\user\CometovArt\Dev\catbot\error.py", line 78, in error_handler
    context.bot.send_message(chat_id=DEV_CHAT, text=message, parse_mode=ParseMode.HTML)
  File "C:\Users\user\AppData\Local\Programs\Python\Python39\lib\site-packages\telegram\bot.py", line 130, in decorator
    result = func(*args, **kwargs)
  File "C:\Users\user\AppData\Local\Programs\Python\Python39\lib\site-packages\telegram\bot.py", line 522, in send_message
    return self._message(  # type: ignore[return-value]
  File "C:\Users\user\AppData\Local\Programs\Python\Python39\lib\site-packages\telegram\ext\extbot.py", line 200, in _message
    result = super()._message(
  File "C:\Users\user\AppData\Local\Programs\Python\Python39\lib\site-packages\telegram\bot.py", line 336, in _message
    result = self._post(endpoint, data, timeout=timeout, api_kwargs=api_kwargs)
  File "C:\Users\user\AppData\Local\Programs\Python\Python39\lib\site-packages\telegram\bot.py", line 295, in _post
    return self.request.post(
  File "C:\Users\user\AppData\Local\Programs\Python\Python39\lib\site-packages\telegram\utils\request.py", line 361, in post
    result = self._request_wrapper(
  File "C:\Users\user\AppData\Local\Programs\Python\Python39\lib\site-packages\telegram\utils\request.py", line 279, in _request_wrapper
    raise BadRequest(message)
telegram.error.BadRequest: Message is too long
