2022-05-15 18:09:53,086 - apscheduler.scheduler - INFO - Scheduler started
2022-05-15 18:09:53,388 - error - ERROR - Exception while handling an update:
Traceback (most recent call last):
  File "C:\Users\user\AppData\Local\Programs\Python\Python39\lib\site-packages\telegram\ext\dispatcher.py", line 555, in process_update
    handler.handle_update(update, self, check, context)
  File "C:\Users\user\AppData\Local\Programs\Python\Python39\lib\site-packages\telegram\ext\handler.py", line 198, in handle_update
    return self.callback(update, context)
  File "c:\Users\user\CometovArt\Dev\catbot\mew.py", line 25, in talk
    update.message.reply_sticker(sticker=random_sticker())
AttributeError: 'NoneType' object has no attribute 'reply_sticker'
2022-05-15 18:09:56,320 - error - ERROR - Exception while handling an update:
Traceback (most recent call last):
  File "C:\Users\user\AppData\Local\Programs\Python\Python39\lib\site-packages\telegram\ext\dispatcher.py", line 555, in process_update
    handler.handle_update(update, self, check, context)
  File "C:\Users\user\AppData\Local\Programs\Python\Python39\lib\site-packages\telegram\ext\handler.py", line 198, in handle_update
    return self.callback(update, context)
  File "c:\Users\user\CometovArt\Dev\catbot\mew.py", line 25, in talk
    update.message.reply_sticker(sticker=random_sticker())
AttributeError: 'NoneType' object has no attribute 'reply_sticker'
2022-05-15 18:15:21,530 - apscheduler.scheduler - INFO - Scheduler started
